Workbook

Sheet sheet1
D2: TABLE
C4: xy | D4: Multiplication | E4: Subsraction | F4: Addition | G4: Division
C5: numbers | D5: 10 | E5: 20 | F5: 30 | G5: 40 | M5: Data
C6: 6 | D6: =C6*$D$5 -> 60 | E6: =$E$5-C6 -> 14 | F6: =$F$5+C6 -> 36 | G6: =$G$5/C6 -> 6.6666667 | M6: no1 | N6: no2
C7: 7 | D7: =C7*$D$5 -> 70 | E7: =$E$5-C7 -> 13 | F7: =$F$5+C7 -> 37 | G7: =$G$5/C7 -> 5.7142857 | M7: 10 | N7: 30
C8: 8 | D8: =C8*$D$5 -> 80 | E8: =$E$5-C8 -> 12 | F8: =$F$5+C8 -> 38 | G8: =$G$5/C8 -> 5 | M8: 20 | N8: 50
C9: 9 | D9: =C9*$D$5 -> 90 | E9: =$E$5-C9 -> 11 | F9: =$F$5+C9 -> 39 | G9: =$G$5/C9 -> 4.4444444 | M9: 30 | N9: 60
C10: 10 | D10: =C10*$D$5 -> 100 | E10: =$E$5-C10 -> 10 | F10: =$F$5+C10 -> 40 | G10: =$G$5/C10 -> 4 | M10: 30 | N10: 60
C11: Sum | D11: =D6+D7+D8+D9+D10 -> 400 | E11: =E6+E7+E8+E9+E10 -> 60 | F11: =F6+F7+F8+F9+F10 -> 190 | G11: =G6+G7+G8+G9+G10 -> 25.825397 | M11: 30 | N11: 60
L15: Table values
K16: no1 | L16: 10 | M16: 20 | N16: 30 | O16: 30 | P16: 30
K17: no2 | L17: 20 | M17: 40 | N17: 60 | O17: 60 | P17: 60
E25: Age | G25: Age group
E26: 19 | G26: =VLOOKUP(E26,Sheet2!G7,2,TRUE) -> #N/A
E27: 21 | G27: =VLOOKUP(E27,Sheet2!G8,2,TRUE) -> #N/A
E28: 20 | G28: =VLOOKUP(E28,Sheet2!G9,2,TRUE) -> #N/A
E29: 23 | G29: =VLOOKUP(E29,Sheet2!G10,2,TRUE) -> #N/A
E30: 31 | G30: =VLOOKUP(E30,Sheet2!G11,2,TRUE) -> #N/A
E31: 22 | G31: =VLOOKUP(E31,Sheet2!G12,2,TRUE) -> #N/A
E32: 35 | G32: =VLOOKUP(E32,Sheet2!G13,2,TRUE) -> #N/A
E33: 40 | G33: =VLOOKUP(E33,Sheet2!G14,2,TRUE) -> #N/A
E34: 18 | G34: =VLOOKUP(E34,Sheet2!G15,2,TRUE) -> #N/A
E35: 50 | G35: =VLOOKUP(E35,Sheet2!G16,2,TRUE) -> #N/A
E36: 25 | G36: =VLOOKUP(E36,Sheet2!G17,2,TRUE) -> #N/A
E37: 26 | G37: =VLOOKUP(E37,Sheet2!G18,2,TRUE) -> #N/A
... E49: 32 | G49: =VLOOKUP(E49,Sheet2!G30,2,TRUE) -> #N/A

Sheet Sheet2
G7: Age group | H7: AGE
G8: under 20 | H8: 0.02
G9: 20-30 | H9: 0.11
G10: 31-40 | H10: 0.07
G11: 41-50 | H11: 0.03
D39: S.no | E39: Spending_Score | F39: Spending Percentage
D40: 1 | E40: under 30 | F40: 4
D41: 2 | E41: 30-50 | F41: 8
D42: 3 | E42: 51-60 | F42: 2
D43: 4 | E43: 61-70 | F43: 2
D44: 5 | E44: 71-80 | F44: 3
D45: 6 | E45: 81-90 | F45: 3
D95: Customer Number | E95: Number of Items Purchased | F95: Total Amount (USD)
D96: 1001 | E96: 3 | F96: 45
D97: 1002 | E97: 5 | F97: 75
D98: 1003 | E98: 2 | F98: 30
D99: 1004 | E99: 8 | F99: 120
D100: 1005 | E100: 4 | F100: 60
D101: 1006 | E101: 10 | F101: 150
D102: 1007 | E102: 6 | F102: 90
D103: 1008 | E103: 7 | F103: 105
D104: 1009 | E104: 1 | F104: 15
D105: 1010 | E105: 9 | F105: 135
D106: 1011 | E106: 3 | F106: 45
D107: 1012 | E107: 12 | F107: 180
... D125: 1030 | E125: 2 | F125: 30
D126: Total | E126: =SUM(E96:E125) -> 201 | F126: =SUM(F96:F125) -> 3015
C134: S.no | D134: Amount | E134: Customers | F134: Percentage
C135: 1 | D135: Less than 50 | E135: 8 | F135: 0.27
C136: 2 | D136: 50-100 | E136: 8 | F136: 0.28
C137: 3 | D137: 101-150 | E137: 7 | F137: 0.24
C138: 4 | D138: 151-200 | E138: 4 | F138: 0.14
C139: 5 | D139: More than 200 | E139: 2 | F139: 0.07
C140: Total | E140: =SUM(E135:E139) -> 29 | F140: =SUM(F135:F139) -> 1
E185: S.no | F185: Amount | G185: Items | H185: Percentage
E186: 1 | F186: Less than 10
E187: 2
E188: 3 | F188: 101-150
E189: 4 | F189: 151-200
E190: 5 | F190: More than 200
...

Sheet Sheet3

Sheet Sheet4
